<?xml version="1.0"?>
<robot name="my_robot">

  <material name="blue">
    <color rgba="0.0 0.0 0.8 1.0"/>
  </material>

  <material name="black">
    <color rgba="0.0 0.0 0.0 1.0"/>
  </material>

  <material name="gray">
    <color rgba="0.7 0.7 0.7 1.0"/>
  </material>

  <link name="base_link">
    <visual>
      <origin xyz="0 0 0.02" rpy="0 0 0"/>
      <geometry>
        <mesh filename="package://robot_build/meshes/body.stl"/>
      </geometry>
      <material name="blue"/>
    </visual>
    <collision>
      <origin xyz="0 0 0.125" rpy="0 0 0"/>
      <geometry>
        <cylinder length="0.25" radius="0.105"/>
      </geometry>
    </collision>
    <inertial>
      <mass value="50.0"/>
      <inertia ixx="10.0" ixy="0.0" ixz="0.0" iyy="10.0" iyz="0.0" izz="10.0"/>
    </inertial>
  </link>

  <link name="left_wheel">
    <visual>
      <geometry>
        <mesh filename="package://robot_build/meshes/wheel.stl"/>
      </geometry>
      <material name="black"/>
    </visual>
    <collision>
      <origin xyz="0.0 0.0 0.0" rpy="-1.57 0 0"/>
      <geometry>
        <cylinder length="0.01" radius="0.02"/>
      </geometry>
    </collision>
    <inertial>
      <mass value="5.0"/>
      <inertia ixx="0.1" ixy="0.0" ixz="0.0" iyy="0.1" iyz="0.0" izz="0.1"/>
    </inertial>
  </link>

  <link name="right_wheel">
    <visual>
      <geometry>
        <mesh filename="package://robot_build/meshes/wheel.stl"/>
      </geometry>
      <material name="black"/>
    </visual>
    <collision>
      <origin xyz="0.0 0.0 0.0" rpy="1.57 0 0"/>
      <geometry>
        <cylinder length="0.01" radius="0.02"/>
      </geometry>
    </collision>
    <inertial>
      <mass value="5.0"/>
      <inertia ixx="0.1" ixy="0.0" ixz="0.0" iyy="0.1" iyz="0.0" izz="0.1"/>
    </inertial>
  </link>

  <link name="front_caster">
    <visual>
      <geometry>
        <mesh filename="package://robot_build/meshes/ball.stl"/>
      </geometry>
      <material name="gray"/>
    </visual>
    <collision>
      <origin xyz="0.0 0.0 0.0" rpy="0 0 0"/>
      <geometry>
        <sphere radius="0.02"/>
      </geometry>
    </collision>
    <inertial>
      <mass value="2.0"/>
      <inertia ixx="0.01" ixy="0.0" ixz="0.0" iyy="0.01" iyz="0.0" izz="0.01"/>
    </inertial>
  </link>

  <joint name="left_wheel_joint" type="continuous">
    <parent link="base_link"/>
    <child link="left_wheel"/>
    <origin xyz="-0.02 0.06 0.02" rpy="0 0 0"/>
    <axis xyz="0 1 0"/>
    <dynamics damping="0.1" friction="0.0"/>
  </joint>

  <joint name="right_wheel_joint" type="continuous">
    <parent link="base_link"/>
    <child link="right_wheel"/>
    <origin xyz="-0.02 -0.06 0.02" rpy="3.141516 0 0"/>
    <axis xyz="0 1 0"/>
    <dynamics damping="0.1" friction="0.0"/>
  </joint>

  <joint name="front_caster_joint" type="fixed">
    <parent link="base_link"/>
    <child link="front_caster"/>
    <origin xyz="0.03 0.0 0.02" rpy="0 0 0"/>
  </joint>

</robot>